<?xml version="1.0" encoding="UTF-8"?>
<testng-results skipped="0" failed="2" ignored="0" total="3" passed="1">
  <reporter-output>
  </reporter-output>
  <suite name="Default suite" duration-ms="54526" started-at="2019-11-27T23:34:08Z" finished-at="2019-11-27T23:35:02Z">
    <groups>
    </groups>
    <test name="Default test" duration-ms="54526" started-at="2019-11-27T23:34:08Z" finished-at="2019-11-27T23:35:02Z">
      <class name="testcases.TestCase04DataDriven">
        <test-method status="FAIL" signature="verifylogin(java.lang.String, java.lang.String)[pri:0, instance:testcases.TestCase04DataDriven@5442a311]" name="verifylogin" duration-ms="17747" started-at="2019-11-27T23:34:08Z" data-provider="banking" finished-at="2019-11-27T23:34:25Z">
          <params>
            <param index="0">
              <value>
                <![CDATA[username]]>
              </value>
            </param>
            <param index="1">
              <value>
                <![CDATA[Password1]]>
              </value>
            </param>
          </params>
          <exception class="java.lang.AssertionError">
            <message>
              <![CDATA[User not login Invalid Credentials expected [true] but found [false]]]>
            </message>
            <full-stacktrace>
              <![CDATA[java.lang.AssertionError: User not login Invalid Credentials expected [true] but found [false]
at org.testng.Assert.fail(Assert.java:96)
at org.testng.Assert.failNotEquals(Assert.java:776)
at org.testng.Assert.assertTrue(Assert.java:44)
at testcases.TestCase04DataDriven.verifylogin(TestCase04DataDriven.java:32)
at sun.reflect.NativeMethodAccessorImpl.invoke0(Native Method)
at sun.reflect.NativeMethodAccessorImpl.invoke(Unknown Source)
at sun.reflect.DelegatingMethodAccessorImpl.invoke(Unknown Source)
at java.lang.reflect.Method.invoke(Unknown Source)
at org.testng.internal.MethodInvocationHelper.invokeMethod(MethodInvocationHelper.java:124)
at org.testng.internal.Invoker.invokeMethod(Invoker.java:583)
at org.testng.internal.Invoker.invokeTestMethod(Invoker.java:719)
at org.testng.internal.Invoker.invokeTestMethods(Invoker.java:989)
at org.testng.internal.TestMethodWorker.invokeTestMethods(TestMethodWorker.java:125)
at org.testng.internal.TestMethodWorker.run(TestMethodWorker.java:109)
at org.testng.TestRunner.privateRun(TestRunner.java:648)
at org.testng.TestRunner.run(TestRunner.java:505)
at org.testng.SuiteRunner.runTest(SuiteRunner.java:455)
at org.testng.SuiteRunner.runSequentially(SuiteRunner.java:450)
at org.testng.SuiteRunner.privateRun(SuiteRunner.java:415)
at org.testng.SuiteRunner.run(SuiteRunner.java:364)
at org.testng.SuiteRunnerWorker.runSuite(SuiteRunnerWorker.java:52)
at org.testng.SuiteRunnerWorker.run(SuiteRunnerWorker.java:84)
at org.testng.TestNG.runSuitesSequentially(TestNG.java:1208)
at org.testng.TestNG.runSuitesLocally(TestNG.java:1137)
at org.testng.TestNG.runSuites(TestNG.java:1049)
at org.testng.TestNG.run(TestNG.java:1017)
at org.testng.remote.AbstractRemoteTestNG.run(AbstractRemoteTestNG.java:115)
at org.testng.remote.RemoteTestNG.initAndRun(RemoteTestNG.java:251)
at org.testng.remote.RemoteTestNG.main(RemoteTestNG.java:77)
]]>
            </full-stacktrace>
          </exception> <!-- java.lang.AssertionError -->
          <reporter-output>
          </reporter-output>
        </test-method> <!-- verifylogin -->
        <test-method status="PASS" signature="teardown()[pri:0, instance:testcases.TestCase04DataDriven@5442a311]" name="teardown" is-config="true" duration-ms="1361" started-at="2019-11-27T23:34:25Z" finished-at="2019-11-27T23:34:27Z">
          <reporter-output>
          </reporter-output>
        </test-method> <!-- teardown -->
        <test-method status="PASS" signature="verifylogin(java.lang.String, java.lang.String)[pri:0, instance:testcases.TestCase04DataDriven@5442a311]" name="verifylogin" duration-ms="17326" started-at="2019-11-27T23:34:27Z" data-provider="banking" finished-at="2019-11-27T23:34:44Z">
          <params>
            <param index="0">
              <value>
                <![CDATA[username]]>
              </value>
            </param>
            <param index="1">
              <value>
                <![CDATA[password]]>
              </value>
            </param>
          </params>
          <reporter-output>
          </reporter-output>
        </test-method> <!-- verifylogin -->
        <test-method status="PASS" signature="teardown()[pri:0, instance:testcases.TestCase04DataDriven@5442a311]" name="teardown" is-config="true" duration-ms="776" started-at="2019-11-27T23:34:44Z" finished-at="2019-11-27T23:34:45Z">
          <reporter-output>
          </reporter-output>
        </test-method> <!-- teardown -->
        <test-method status="FAIL" signature="verifylogin(java.lang.String, java.lang.String)[pri:0, instance:testcases.TestCase04DataDriven@5442a311]" name="verifylogin" duration-ms="16474" started-at="2019-11-27T23:34:45Z" data-provider="banking" finished-at="2019-11-27T23:35:01Z">
          <params>
            <param index="0">
              <value>
                <![CDATA[username]]>
              </value>
            </param>
            <param index="1">
              <value>
                <![CDATA[Password2]]>
              </value>
            </param>
          </params>
          <exception class="java.lang.AssertionError">
            <message>
              <![CDATA[User not login Invalid Credentials expected [true] but found [false]]]>
            </message>
            <full-stacktrace>
              <![CDATA[java.lang.AssertionError: User not login Invalid Credentials expected [true] but found [false]
at org.testng.Assert.fail(Assert.java:96)
at org.testng.Assert.failNotEquals(Assert.java:776)
at org.testng.Assert.assertTrue(Assert.java:44)
at testcases.TestCase04DataDriven.verifylogin(TestCase04DataDriven.java:32)
at sun.reflect.NativeMethodAccessorImpl.invoke0(Native Method)
at sun.reflect.NativeMethodAccessorImpl.invoke(Unknown Source)
at sun.reflect.DelegatingMethodAccessorImpl.invoke(Unknown Source)
at java.lang.reflect.Method.invoke(Unknown Source)
at org.testng.internal.MethodInvocationHelper.invokeMethod(MethodInvocationHelper.java:124)
at org.testng.internal.Invoker.invokeMethod(Invoker.java:583)
at org.testng.internal.Invoker.invokeTestMethod(Invoker.java:719)
at org.testng.internal.Invoker.invokeTestMethods(Invoker.java:989)
at org.testng.internal.TestMethodWorker.invokeTestMethods(TestMethodWorker.java:125)
at org.testng.internal.TestMethodWorker.run(TestMethodWorker.java:109)
at org.testng.TestRunner.privateRun(TestRunner.java:648)
at org.testng.TestRunner.run(TestRunner.java:505)
at org.testng.SuiteRunner.runTest(SuiteRunner.java:455)
at org.testng.SuiteRunner.runSequentially(SuiteRunner.java:450)
at org.testng.SuiteRunner.privateRun(SuiteRunner.java:415)
at org.testng.SuiteRunner.run(SuiteRunner.java:364)
at org.testng.SuiteRunnerWorker.runSuite(SuiteRunnerWorker.java:52)
at org.testng.SuiteRunnerWorker.run(SuiteRunnerWorker.java:84)
at org.testng.TestNG.runSuitesSequentially(TestNG.java:1208)
at org.testng.TestNG.runSuitesLocally(TestNG.java:1137)
at org.testng.TestNG.runSuites(TestNG.java:1049)
at org.testng.TestNG.run(TestNG.java:1017)
at org.testng.remote.AbstractRemoteTestNG.run(AbstractRemoteTestNG.java:115)
at org.testng.remote.RemoteTestNG.initAndRun(RemoteTestNG.java:251)
at org.testng.remote.RemoteTestNG.main(RemoteTestNG.java:77)
]]>
            </full-stacktrace>
          </exception> <!-- java.lang.AssertionError -->
          <reporter-output>
          </reporter-output>
        </test-method> <!-- verifylogin -->
        <test-method status="PASS" signature="teardown()[pri:0, instance:testcases.TestCase04DataDriven@5442a311]" name="teardown" is-config="true" duration-ms="787" started-at="2019-11-27T23:35:01Z" finished-at="2019-11-27T23:35:02Z">
          <reporter-output>
          </reporter-output>
        </test-method> <!-- teardown -->
      </class> <!-- testcases.TestCase04DataDriven -->
    </test> <!-- Default test -->
  </suite> <!-- Default suite -->
</testng-results>
